[2024-04-08T17:10:34.343+0000] {taskinstance.py:1159} INFO - Dependencies all met for dep_context=non-requeueable deps ti=<TaskInstance: seed_initial_data.insert_coins_into_db manual__2024-04-08T17:10:32.755595+00:00 [queued]>
[2024-04-08T17:10:34.348+0000] {taskinstance.py:1159} INFO - Dependencies all met for dep_context=requeueable deps ti=<TaskInstance: seed_initial_data.insert_coins_into_db manual__2024-04-08T17:10:32.755595+00:00 [queued]>
[2024-04-08T17:10:34.349+0000] {taskinstance.py:1361} INFO - Starting attempt 1 of 1
[2024-04-08T17:10:34.357+0000] {taskinstance.py:1382} INFO - Executing <Task(PythonOperator): insert_coins_into_db> on 2024-04-08 17:10:32.755595+00:00
[2024-04-08T17:10:34.361+0000] {standard_task_runner.py:57} INFO - Started process 6808 to run task
[2024-04-08T17:10:34.364+0000] {standard_task_runner.py:84} INFO - Running: ['***', 'tasks', 'run', 'seed_initial_data', 'insert_coins_into_db', 'manual__2024-04-08T17:10:32.755595+00:00', '--job-id', '20', '--raw', '--subdir', 'DAGS_FOLDER/file_procesor_dag.py', '--cfg-path', '/tmp/tmpn80q653k']
[2024-04-08T17:10:34.367+0000] {standard_task_runner.py:85} INFO - Job 20: Subtask insert_coins_into_db
[2024-04-08T17:10:34.426+0000] {task_command.py:416} INFO - Running <TaskInstance: seed_initial_data.insert_coins_into_db manual__2024-04-08T17:10:32.755595+00:00 [running]> on host 2c889d8e7a74
[2024-04-08T17:10:34.490+0000] {taskinstance.py:1662} INFO - Exporting env vars: AIRFLOW_CTX_DAG_OWNER='***' AIRFLOW_CTX_DAG_ID='seed_initial_data' AIRFLOW_CTX_TASK_ID='insert_coins_into_db' AIRFLOW_CTX_EXECUTION_DATE='2024-04-08T17:10:32.755595+00:00' AIRFLOW_CTX_TRY_NUMBER='1' AIRFLOW_CTX_DAG_RUN_ID='manual__2024-04-08T17:10:32.755595+00:00'
[2024-04-08T17:10:34.492+0000] {taskinstance.py:1937} ERROR - Task failed with exception
Traceback (most recent call last):
  File "/home/airflow/.local/lib/python3.8/site-packages/airflow/operators/python.py", line 192, in execute
    return_value = self.execute_callable()
  File "/home/airflow/.local/lib/python3.8/site-packages/airflow/operators/python.py", line 209, in execute_callable
    return self.python_callable(*self.op_args, **self.op_kwargs)
  File "/opt/airflow/scripts/main.py", line 9, in procesar_archivo
    config = load_json_file(params['path'])
KeyError: 'path'
[2024-04-08T17:10:34.503+0000] {taskinstance.py:1400} INFO - Marking task as FAILED. dag_id=seed_initial_data, task_id=insert_coins_into_db, execution_date=20240408T171032, start_date=20240408T171034, end_date=20240408T171034
[2024-04-08T17:10:34.509+0000] {standard_task_runner.py:104} ERROR - Failed to execute job 20 for task insert_coins_into_db ('path'; 6808)
[2024-04-08T17:10:34.537+0000] {local_task_job_runner.py:228} INFO - Task exited with return code 1
[2024-04-08T17:10:34.554+0000] {taskinstance.py:2778} INFO - 0 downstream tasks scheduled from follow-on schedule check
