[2024-04-08T20:52:00.752+0000] {taskinstance.py:1159} INFO - Dependencies all met for dep_context=non-requeueable deps ti=<TaskInstance: seed_initial_data.insert_coins_into_db manual__2024-04-08T20:51:58.505248+00:00 [queued]>
[2024-04-08T20:52:00.759+0000] {taskinstance.py:1159} INFO - Dependencies all met for dep_context=requeueable deps ti=<TaskInstance: seed_initial_data.insert_coins_into_db manual__2024-04-08T20:51:58.505248+00:00 [queued]>
[2024-04-08T20:52:00.761+0000] {taskinstance.py:1361} INFO - Starting attempt 1 of 1
[2024-04-08T20:52:00.768+0000] {taskinstance.py:1382} INFO - Executing <Task(PythonOperator): insert_coins_into_db> on 2024-04-08 20:51:58.505248+00:00
[2024-04-08T20:52:00.773+0000] {standard_task_runner.py:57} INFO - Started process 41791 to run task
[2024-04-08T20:52:00.776+0000] {standard_task_runner.py:84} INFO - Running: ['***', 'tasks', 'run', 'seed_initial_data', 'insert_coins_into_db', 'manual__2024-04-08T20:51:58.505248+00:00', '--job-id', '38', '--raw', '--subdir', 'DAGS_FOLDER/file_procesor_dag.py', '--cfg-path', '/tmp/tmpawk0axow']
[2024-04-08T20:52:00.780+0000] {standard_task_runner.py:85} INFO - Job 38: Subtask insert_coins_into_db
[2024-04-08T20:52:00.828+0000] {task_command.py:416} INFO - Running <TaskInstance: seed_initial_data.insert_coins_into_db manual__2024-04-08T20:51:58.505248+00:00 [running]> on host 2c889d8e7a74
[2024-04-08T20:52:00.898+0000] {taskinstance.py:1662} INFO - Exporting env vars: AIRFLOW_CTX_DAG_OWNER='***' AIRFLOW_CTX_DAG_ID='seed_initial_data' AIRFLOW_CTX_TASK_ID='insert_coins_into_db' AIRFLOW_CTX_EXECUTION_DATE='2024-04-08T20:51:58.505248+00:00' AIRFLOW_CTX_TRY_NUMBER='1' AIRFLOW_CTX_DAG_RUN_ID='manual__2024-04-08T20:51:58.505248+00:00'
[2024-04-08T20:52:01.081+0000] {taskinstance.py:1937} ERROR - Task failed with exception
Traceback (most recent call last):
  File "/home/airflow/.local/lib/python3.8/site-packages/airflow/operators/python.py", line 192, in execute
    return_value = self.execute_callable()
  File "/home/airflow/.local/lib/python3.8/site-packages/airflow/operators/python.py", line 209, in execute_callable
    return self.python_callable(*self.op_args, **self.op_kwargs)
  File "/opt/airflow/scripts/main.py", line 27, in procesar_archivo
    raise ValueError(f"File already exists: {final_path}")
ValueError: File already exists: scripts/data/output/nyse_2012.parquet
[2024-04-08T20:52:01.092+0000] {taskinstance.py:1400} INFO - Marking task as FAILED. dag_id=seed_initial_data, task_id=insert_coins_into_db, execution_date=20240408T205158, start_date=20240408T205200, end_date=20240408T205201
[2024-04-08T20:52:01.099+0000] {standard_task_runner.py:104} ERROR - Failed to execute job 38 for task insert_coins_into_db (File already exists: scripts/data/output/nyse_2012.parquet; 41791)
[2024-04-08T20:52:01.155+0000] {local_task_job_runner.py:228} INFO - Task exited with return code 1
[2024-04-08T20:52:01.173+0000] {taskinstance.py:2778} INFO - 0 downstream tasks scheduled from follow-on schedule check
