[2024-04-08T17:11:08.711+0000] {taskinstance.py:1159} INFO - Dependencies all met for dep_context=non-requeueable deps ti=<TaskInstance: seed_initial_data.insert_coins_into_db manual__2024-04-08T17:11:07.145939+00:00 [queued]>
[2024-04-08T17:11:08.717+0000] {taskinstance.py:1159} INFO - Dependencies all met for dep_context=requeueable deps ti=<TaskInstance: seed_initial_data.insert_coins_into_db manual__2024-04-08T17:11:07.145939+00:00 [queued]>
[2024-04-08T17:11:08.718+0000] {taskinstance.py:1361} INFO - Starting attempt 1 of 1
[2024-04-08T17:11:08.725+0000] {taskinstance.py:1382} INFO - Executing <Task(PythonOperator): insert_coins_into_db> on 2024-04-08 17:11:07.145939+00:00
[2024-04-08T17:11:08.729+0000] {standard_task_runner.py:57} INFO - Started process 7162 to run task
[2024-04-08T17:11:08.733+0000] {standard_task_runner.py:84} INFO - Running: ['***', 'tasks', 'run', 'seed_initial_data', 'insert_coins_into_db', 'manual__2024-04-08T17:11:07.145939+00:00', '--job-id', '21', '--raw', '--subdir', 'DAGS_FOLDER/file_procesor_dag.py', '--cfg-path', '/tmp/tmpb51x4x4i']
[2024-04-08T17:11:08.736+0000] {standard_task_runner.py:85} INFO - Job 21: Subtask insert_coins_into_db
[2024-04-08T17:11:08.777+0000] {task_command.py:416} INFO - Running <TaskInstance: seed_initial_data.insert_coins_into_db manual__2024-04-08T17:11:07.145939+00:00 [running]> on host 2c889d8e7a74
[2024-04-08T17:11:08.837+0000] {taskinstance.py:1662} INFO - Exporting env vars: AIRFLOW_CTX_DAG_OWNER='***' AIRFLOW_CTX_DAG_ID='seed_initial_data' AIRFLOW_CTX_TASK_ID='insert_coins_into_db' AIRFLOW_CTX_EXECUTION_DATE='2024-04-08T17:11:07.145939+00:00' AIRFLOW_CTX_TRY_NUMBER='1' AIRFLOW_CTX_DAG_RUN_ID='manual__2024-04-08T17:11:07.145939+00:00'
[2024-04-08T17:11:08.839+0000] {taskinstance.py:1937} ERROR - Task failed with exception
Traceback (most recent call last):
  File "/home/airflow/.local/lib/python3.8/site-packages/airflow/operators/python.py", line 192, in execute
    return_value = self.execute_callable()
  File "/home/airflow/.local/lib/python3.8/site-packages/airflow/operators/python.py", line 209, in execute_callable
    return self.python_callable(*self.op_args, **self.op_kwargs)
  File "/opt/airflow/scripts/main.py", line 13, in procesar_archivo
    strategy = get_strategy(config['metadata']['type'])
  File "/opt/airflow/scripts/strategies/read.py", line 36, in get_strategy
    raise ValueError(f"Invalid strategy: {strategy}")
ValueError: Invalid strategy: None
[2024-04-08T17:11:08.850+0000] {taskinstance.py:1400} INFO - Marking task as FAILED. dag_id=seed_initial_data, task_id=insert_coins_into_db, execution_date=20240408T171107, start_date=20240408T171108, end_date=20240408T171108
[2024-04-08T17:11:08.857+0000] {standard_task_runner.py:104} ERROR - Failed to execute job 21 for task insert_coins_into_db (Invalid strategy: None; 7162)
[2024-04-08T17:11:08.906+0000] {local_task_job_runner.py:228} INFO - Task exited with return code 1
[2024-04-08T17:11:08.924+0000] {taskinstance.py:2778} INFO - 0 downstream tasks scheduled from follow-on schedule check
