[2024-04-08T20:18:58.233+0000] {taskinstance.py:1159} INFO - Dependencies all met for dep_context=non-requeueable deps ti=<TaskInstance: seed_initial_data.insert_coins_into_db manual__2024-04-08T20:18:55.817912+00:00 [queued]>
[2024-04-08T20:18:58.238+0000] {taskinstance.py:1159} INFO - Dependencies all met for dep_context=requeueable deps ti=<TaskInstance: seed_initial_data.insert_coins_into_db manual__2024-04-08T20:18:55.817912+00:00 [queued]>
[2024-04-08T20:18:58.239+0000] {taskinstance.py:1361} INFO - Starting attempt 1 of 1
[2024-04-08T20:18:58.247+0000] {taskinstance.py:1382} INFO - Executing <Task(PythonOperator): insert_coins_into_db> on 2024-04-08 20:18:55.817912+00:00
[2024-04-08T20:18:58.251+0000] {standard_task_runner.py:57} INFO - Started process 21770 to run task
[2024-04-08T20:18:58.254+0000] {standard_task_runner.py:84} INFO - Running: ['***', 'tasks', 'run', 'seed_initial_data', 'insert_coins_into_db', 'manual__2024-04-08T20:18:55.817912+00:00', '--job-id', '36', '--raw', '--subdir', 'DAGS_FOLDER/file_procesor_dag.py', '--cfg-path', '/tmp/tmppc1_21rk']
[2024-04-08T20:18:58.257+0000] {standard_task_runner.py:85} INFO - Job 36: Subtask insert_coins_into_db
[2024-04-08T20:18:58.303+0000] {task_command.py:416} INFO - Running <TaskInstance: seed_initial_data.insert_coins_into_db manual__2024-04-08T20:18:55.817912+00:00 [running]> on host 2c889d8e7a74
[2024-04-08T20:18:58.364+0000] {taskinstance.py:1662} INFO - Exporting env vars: AIRFLOW_CTX_DAG_OWNER='***' AIRFLOW_CTX_DAG_ID='seed_initial_data' AIRFLOW_CTX_TASK_ID='insert_coins_into_db' AIRFLOW_CTX_EXECUTION_DATE='2024-04-08T20:18:55.817912+00:00' AIRFLOW_CTX_TRY_NUMBER='1' AIRFLOW_CTX_DAG_RUN_ID='manual__2024-04-08T20:18:55.817912+00:00'
[2024-04-08T20:18:58.826+0000] {taskinstance.py:1937} ERROR - Task failed with exception
Traceback (most recent call last):
  File "/home/airflow/.local/lib/python3.8/site-packages/airflow/operators/python.py", line 192, in execute
    return_value = self.execute_callable()
  File "/home/airflow/.local/lib/python3.8/site-packages/airflow/operators/python.py", line 209, in execute_callable
    return self.python_callable(*self.op_args, **self.op_kwargs)
  File "/opt/airflow/scripts/main.py", line 33, in procesar_archivo
    df.to_parquet(final_path, partition_cols=[config['partition_by']])
  File "/home/airflow/.local/lib/python3.8/site-packages/pandas/core/frame.py", line 2889, in to_parquet
    return to_parquet(
  File "/home/airflow/.local/lib/python3.8/site-packages/pandas/io/parquet.py", line 411, in to_parquet
    impl.write(
  File "/home/airflow/.local/lib/python3.8/site-packages/pandas/io/parquet.py", line 180, in write
    self.api.parquet.write_to_dataset(
  File "/home/airflow/.local/lib/python3.8/site-packages/pyarrow/parquet/core.py", line 3388, in write_to_dataset
    ds.write_dataset(
  File "/home/airflow/.local/lib/python3.8/site-packages/pyarrow/dataset.py", line 998, in write_dataset
    _filesystemdataset_write(
  File "pyarrow/_dataset.pyx", line 3016, in pyarrow._dataset._filesystemdataset_write
  File "pyarrow/error.pxi", line 113, in pyarrow.lib.check_status
NotADirectoryError: [Errno 20] Cannot create directory 'scripts/data/output/nyse_2012.parquet/transaction_date=02-Jun-2012'. Detail: [errno 20] Not a directory
[2024-04-08T20:18:58.838+0000] {taskinstance.py:1400} INFO - Marking task as FAILED. dag_id=seed_initial_data, task_id=insert_coins_into_db, execution_date=20240408T201855, start_date=20240408T201858, end_date=20240408T201858
[2024-04-08T20:18:58.846+0000] {standard_task_runner.py:104} ERROR - Failed to execute job 36 for task insert_coins_into_db ([Errno 20] Cannot create directory 'scripts/data/output/nyse_2012.parquet/transaction_date=02-Jun-2012'. Detail: [errno 20] Not a directory; 21770)
[2024-04-08T20:18:58.920+0000] {local_task_job_runner.py:228} INFO - Task exited with return code 1
[2024-04-08T20:18:58.938+0000] {taskinstance.py:2778} INFO - 0 downstream tasks scheduled from follow-on schedule check
