[2024-04-08T20:12:09.801+0000] {taskinstance.py:1159} INFO - Dependencies all met for dep_context=non-requeueable deps ti=<TaskInstance: seed_initial_data.insert_coins_into_db manual__2024-04-08T20:12:07.962893+00:00 [queued]>
[2024-04-08T20:12:09.806+0000] {taskinstance.py:1159} INFO - Dependencies all met for dep_context=requeueable deps ti=<TaskInstance: seed_initial_data.insert_coins_into_db manual__2024-04-08T20:12:07.962893+00:00 [queued]>
[2024-04-08T20:12:09.807+0000] {taskinstance.py:1361} INFO - Starting attempt 1 of 1
[2024-04-08T20:12:09.814+0000] {taskinstance.py:1382} INFO - Executing <Task(PythonOperator): insert_coins_into_db> on 2024-04-08 20:12:07.962893+00:00
[2024-04-08T20:12:09.818+0000] {standard_task_runner.py:57} INFO - Started process 17197 to run task
[2024-04-08T20:12:09.822+0000] {standard_task_runner.py:84} INFO - Running: ['***', 'tasks', 'run', 'seed_initial_data', 'insert_coins_into_db', 'manual__2024-04-08T20:12:07.962893+00:00', '--job-id', '34', '--raw', '--subdir', 'DAGS_FOLDER/file_procesor_dag.py', '--cfg-path', '/tmp/tmpn7lbxnkb']
[2024-04-08T20:12:09.825+0000] {standard_task_runner.py:85} INFO - Job 34: Subtask insert_coins_into_db
[2024-04-08T20:12:09.874+0000] {task_command.py:416} INFO - Running <TaskInstance: seed_initial_data.insert_coins_into_db manual__2024-04-08T20:12:07.962893+00:00 [running]> on host 2c889d8e7a74
[2024-04-08T20:12:09.942+0000] {taskinstance.py:1662} INFO - Exporting env vars: AIRFLOW_CTX_DAG_OWNER='***' AIRFLOW_CTX_DAG_ID='seed_initial_data' AIRFLOW_CTX_TASK_ID='insert_coins_into_db' AIRFLOW_CTX_EXECUTION_DATE='2024-04-08T20:12:07.962893+00:00' AIRFLOW_CTX_TRY_NUMBER='1' AIRFLOW_CTX_DAG_RUN_ID='manual__2024-04-08T20:12:07.962893+00:00'
[2024-04-08T20:12:10.238+0000] {taskinstance.py:1937} ERROR - Task failed with exception
Traceback (most recent call last):
  File "/home/airflow/.local/lib/python3.8/site-packages/airflow/operators/python.py", line 192, in execute
    return_value = self.execute_callable()
  File "/home/airflow/.local/lib/python3.8/site-packages/airflow/operators/python.py", line 209, in execute_callable
    return self.python_callable(*self.op_args, **self.op_kwargs)
  File "/opt/airflow/scripts/main.py", line 33, in procesar_archivo
    df.to_parquet(final_path, partition_cols=[config['partition_by']])
  File "/home/airflow/.local/lib/python3.8/site-packages/pandas/core/frame.py", line 2889, in to_parquet
    return to_parquet(
  File "/home/airflow/.local/lib/python3.8/site-packages/pandas/io/parquet.py", line 411, in to_parquet
    impl.write(
  File "/home/airflow/.local/lib/python3.8/site-packages/pandas/io/parquet.py", line 180, in write
    self.api.parquet.write_to_dataset(
  File "/home/airflow/.local/lib/python3.8/site-packages/pyarrow/parquet/core.py", line 3388, in write_to_dataset
    ds.write_dataset(
  File "/home/airflow/.local/lib/python3.8/site-packages/pyarrow/dataset.py", line 998, in write_dataset
    _filesystemdataset_write(
  File "pyarrow/_dataset.pyx", line 3016, in pyarrow._dataset._filesystemdataset_write
  File "pyarrow/error.pxi", line 100, in pyarrow.lib.check_status
pyarrow.lib.ArrowInvalid: Fragment would be written into 2580 partitions. This exceeds the maximum of 1024
[2024-04-08T20:12:10.253+0000] {taskinstance.py:1400} INFO - Marking task as FAILED. dag_id=seed_initial_data, task_id=insert_coins_into_db, execution_date=20240408T201207, start_date=20240408T201209, end_date=20240408T201210
[2024-04-08T20:12:10.260+0000] {standard_task_runner.py:104} ERROR - Failed to execute job 34 for task insert_coins_into_db (Fragment would be written into 2580 partitions. This exceeds the maximum of 1024; 17197)
[2024-04-08T20:12:10.316+0000] {local_task_job_runner.py:228} INFO - Task exited with return code 1
[2024-04-08T20:12:10.339+0000] {taskinstance.py:2778} INFO - 0 downstream tasks scheduled from follow-on schedule check
