[2024-04-08T19:22:58.727+0000] {taskinstance.py:1159} INFO - Dependencies all met for dep_context=non-requeueable deps ti=<TaskInstance: seed_initial_data.insert_coins_into_db manual__2024-04-08T19:22:56.485789+00:00 [queued]>
[2024-04-08T19:22:58.737+0000] {taskinstance.py:1159} INFO - Dependencies all met for dep_context=requeueable deps ti=<TaskInstance: seed_initial_data.insert_coins_into_db manual__2024-04-08T19:22:56.485789+00:00 [queued]>
[2024-04-08T19:22:58.738+0000] {taskinstance.py:1361} INFO - Starting attempt 1 of 1
[2024-04-08T19:22:58.747+0000] {taskinstance.py:1382} INFO - Executing <Task(PythonOperator): insert_coins_into_db> on 2024-04-08 19:22:56.485789+00:00
[2024-04-08T19:22:58.751+0000] {standard_task_runner.py:57} INFO - Started process 87026 to run task
[2024-04-08T19:22:58.755+0000] {standard_task_runner.py:84} INFO - Running: ['***', 'tasks', 'run', 'seed_initial_data', 'insert_coins_into_db', 'manual__2024-04-08T19:22:56.485789+00:00', '--job-id', '32', '--raw', '--subdir', 'DAGS_FOLDER/file_procesor_dag.py', '--cfg-path', '/tmp/tmp566hxr5g']
[2024-04-08T19:22:58.758+0000] {standard_task_runner.py:85} INFO - Job 32: Subtask insert_coins_into_db
[2024-04-08T19:22:58.809+0000] {task_command.py:416} INFO - Running <TaskInstance: seed_initial_data.insert_coins_into_db manual__2024-04-08T19:22:56.485789+00:00 [running]> on host 2c889d8e7a74
[2024-04-08T19:22:58.885+0000] {taskinstance.py:1662} INFO - Exporting env vars: AIRFLOW_CTX_DAG_OWNER='***' AIRFLOW_CTX_DAG_ID='seed_initial_data' AIRFLOW_CTX_TASK_ID='insert_coins_into_db' AIRFLOW_CTX_EXECUTION_DATE='2024-04-08T19:22:56.485789+00:00' AIRFLOW_CTX_TRY_NUMBER='1' AIRFLOW_CTX_DAG_RUN_ID='manual__2024-04-08T19:22:56.485789+00:00'
[2024-04-08T19:22:59.075+0000] {taskinstance.py:1937} ERROR - Task failed with exception
Traceback (most recent call last):
  File "/home/airflow/.local/lib/python3.8/site-packages/airflow/operators/python.py", line 192, in execute
    return_value = self.execute_callable()
  File "/home/airflow/.local/lib/python3.8/site-packages/airflow/operators/python.py", line 209, in execute_callable
    return self.python_callable(*self.op_args, **self.op_kwargs)
  File "/opt/airflow/scripts/main.py", line 18, in procesar_archivo
    for col, valor in config['metadata']['columnas_adicionales'].items():
KeyError: 'columnas_adicionales'
[2024-04-08T19:22:59.087+0000] {taskinstance.py:1400} INFO - Marking task as FAILED. dag_id=seed_initial_data, task_id=insert_coins_into_db, execution_date=20240408T192256, start_date=20240408T192258, end_date=20240408T192259
[2024-04-08T19:22:59.097+0000] {standard_task_runner.py:104} ERROR - Failed to execute job 32 for task insert_coins_into_db ('columnas_adicionales'; 87026)
[2024-04-08T19:22:59.131+0000] {local_task_job_runner.py:228} INFO - Task exited with return code 1
[2024-04-08T19:22:59.149+0000] {taskinstance.py:2778} INFO - 0 downstream tasks scheduled from follow-on schedule check
